<?xml version="1.0" encoding="UTF-8"?>
<testng-results skipped="0" failed="5" ignored="0" total="25" passed="20">
  <reporter-output>
  </reporter-output>
  <suite name="Suite" duration-ms="224" started-at="2019-08-18T05:12:01Z" finished-at="2019-08-18T05:12:01Z">
    <groups>
    </groups>
    <test name="Test1" duration-ms="66" started-at="2019-08-18T05:12:01Z" finished-at="2019-08-18T05:12:01Z">
      <class name="Test_code.Test_01">
        <test-method status="FAIL" signature="code1()[pri:1, instance:Test_code.Test_01@215be6bb]" name="code1" duration-ms="18" started-at="2019-08-18T05:12:01Z" finished-at="2019-08-18T05:12:01Z">
          <exception class="java.lang.AssertionError">
            <message>
              <![CDATA[Test cases failed as we have false value: FAIL!!!!!!!!!!! expected [true] but found [false]]]>
            </message>
            <full-stacktrace>
              <![CDATA[java.lang.AssertionError: Test cases failed as we have false value: FAIL!!!!!!!!!!! expected [true] but found [false]
at org.testng.Assert.fail(Assert.java:96)
at org.testng.Assert.failNotEquals(Assert.java:776)
at org.testng.Assert.assertTrue(Assert.java:44)
at Test_code.Test_01.code1(Test_01.java:17)
at sun.reflect.NativeMethodAccessorImpl.invoke0(Native Method)
at sun.reflect.NativeMethodAccessorImpl.invoke(Unknown Source)
at sun.reflect.DelegatingMethodAccessorImpl.invoke(Unknown Source)
at java.lang.reflect.Method.invoke(Unknown Source)
at org.testng.internal.MethodInvocationHelper.invokeMethod(MethodInvocationHelper.java:124)
at org.testng.internal.Invoker.invokeMethod(Invoker.java:580)
at org.testng.internal.Invoker.invokeTestMethod(Invoker.java:716)
at org.testng.internal.Invoker.invokeTestMethods(Invoker.java:988)
at org.testng.internal.TestMethodWorker.invokeTestMethods(TestMethodWorker.java:125)
at org.testng.internal.TestMethodWorker.run(TestMethodWorker.java:109)
at org.testng.TestRunner.privateRun(TestRunner.java:648)
at org.testng.TestRunner.run(TestRunner.java:505)
at org.testng.SuiteRunner.runTest(SuiteRunner.java:455)
at org.testng.SuiteRunner.runSequentially(SuiteRunner.java:450)
at org.testng.SuiteRunner.privateRun(SuiteRunner.java:415)
at org.testng.SuiteRunner.run(SuiteRunner.java:364)
at org.testng.SuiteRunnerWorker.runSuite(SuiteRunnerWorker.java:52)
at org.testng.SuiteRunnerWorker.run(SuiteRunnerWorker.java:84)
at org.testng.TestNG.runSuitesSequentially(TestNG.java:1208)
at org.testng.TestNG.runSuitesLocally(TestNG.java:1137)
at org.testng.TestNG.runSuites(TestNG.java:1049)
at org.testng.TestNG.run(TestNG.java:1017)
at org.testng.remote.AbstractRemoteTestNG.run(AbstractRemoteTestNG.java:114)
at org.testng.remote.RemoteTestNG.initAndRun(RemoteTestNG.java:251)
at org.testng.remote.RemoteTestNG.main(RemoteTestNG.java:77)
]]>
            </full-stacktrace>
          </exception> <!-- java.lang.AssertionError -->
          <reporter-output>
          </reporter-output>
        </test-method> <!-- code1 -->
        <test-method status="PASS" signature="code2()[pri:2, instance:Test_code.Test_01@215be6bb]" name="code2" duration-ms="1" started-at="2019-08-18T05:12:01Z" finished-at="2019-08-18T05:12:01Z">
          <reporter-output>
          </reporter-output>
        </test-method> <!-- code2 -->
        <test-method status="PASS" signature="code3()[pri:3, instance:Test_code.Test_01@215be6bb]" name="code3" duration-ms="1" started-at="2019-08-18T05:12:01Z" finished-at="2019-08-18T05:12:01Z">
          <reporter-output>
          </reporter-output>
        </test-method> <!-- code3 -->
        <test-method status="PASS" signature="code4()[pri:4, instance:Test_code.Test_01@215be6bb]" name="code4" duration-ms="2" started-at="2019-08-18T05:12:01Z" finished-at="2019-08-18T05:12:01Z">
          <reporter-output>
          </reporter-output>
        </test-method> <!-- code4 -->
        <test-method status="PASS" signature="code5()[pri:5, instance:Test_code.Test_01@215be6bb]" name="code5" duration-ms="1" started-at="2019-08-18T05:12:01Z" finished-at="2019-08-18T05:12:01Z">
          <reporter-output>
          </reporter-output>
        </test-method> <!-- code5 -->
      </class> <!-- Test_code.Test_01 -->
    </test> <!-- Test1 -->
    <test name="Test2" duration-ms="15" started-at="2019-08-18T05:12:01Z" finished-at="2019-08-18T05:12:01Z">
      <class name="Test_code.Test_01">
        <test-method status="FAIL" signature="code1()[pri:1, instance:Test_code.Test_01@39aeed2f]" name="code1" duration-ms="2" started-at="2019-08-18T05:12:01Z" finished-at="2019-08-18T05:12:01Z">
          <exception class="java.lang.AssertionError">
            <message>
              <![CDATA[Test cases failed as we have false value: FAIL!!!!!!!!!!! expected [true] but found [false]]]>
            </message>
            <full-stacktrace>
              <![CDATA[java.lang.AssertionError: Test cases failed as we have false value: FAIL!!!!!!!!!!! expected [true] but found [false]
at org.testng.Assert.fail(Assert.java:96)
at org.testng.Assert.failNotEquals(Assert.java:776)
at org.testng.Assert.assertTrue(Assert.java:44)
at Test_code.Test_01.code1(Test_01.java:17)
at sun.reflect.NativeMethodAccessorImpl.invoke0(Native Method)
at sun.reflect.NativeMethodAccessorImpl.invoke(Unknown Source)
at sun.reflect.DelegatingMethodAccessorImpl.invoke(Unknown Source)
at java.lang.reflect.Method.invoke(Unknown Source)
at org.testng.internal.MethodInvocationHelper.invokeMethod(MethodInvocationHelper.java:124)
at org.testng.internal.Invoker.invokeMethod(Invoker.java:580)
at org.testng.internal.Invoker.invokeTestMethod(Invoker.java:716)
at org.testng.internal.Invoker.invokeTestMethods(Invoker.java:988)
at org.testng.internal.TestMethodWorker.invokeTestMethods(TestMethodWorker.java:125)
at org.testng.internal.TestMethodWorker.run(TestMethodWorker.java:109)
at org.testng.TestRunner.privateRun(TestRunner.java:648)
at org.testng.TestRunner.run(TestRunner.java:505)
at org.testng.SuiteRunner.runTest(SuiteRunner.java:455)
at org.testng.SuiteRunner.runSequentially(SuiteRunner.java:450)
at org.testng.SuiteRunner.privateRun(SuiteRunner.java:415)
at org.testng.SuiteRunner.run(SuiteRunner.java:364)
at org.testng.SuiteRunnerWorker.runSuite(SuiteRunnerWorker.java:52)
at org.testng.SuiteRunnerWorker.run(SuiteRunnerWorker.java:84)
at org.testng.TestNG.runSuitesSequentially(TestNG.java:1208)
at org.testng.TestNG.runSuitesLocally(TestNG.java:1137)
at org.testng.TestNG.runSuites(TestNG.java:1049)
at org.testng.TestNG.run(TestNG.java:1017)
at org.testng.remote.AbstractRemoteTestNG.run(AbstractRemoteTestNG.java:114)
at org.testng.remote.RemoteTestNG.initAndRun(RemoteTestNG.java:251)
at org.testng.remote.RemoteTestNG.main(RemoteTestNG.java:77)
]]>
            </full-stacktrace>
          </exception> <!-- java.lang.AssertionError -->
          <reporter-output>
          </reporter-output>
        </test-method> <!-- code1 -->
        <test-method status="PASS" signature="code2()[pri:2, instance:Test_code.Test_01@39aeed2f]" name="code2" duration-ms="1" started-at="2019-08-18T05:12:01Z" finished-at="2019-08-18T05:12:01Z">
          <reporter-output>
          </reporter-output>
        </test-method> <!-- code2 -->
        <test-method status="PASS" signature="code3()[pri:3, instance:Test_code.Test_01@39aeed2f]" name="code3" duration-ms="1" started-at="2019-08-18T05:12:01Z" finished-at="2019-08-18T05:12:01Z">
          <reporter-output>
          </reporter-output>
        </test-method> <!-- code3 -->
        <test-method status="PASS" signature="code4()[pri:4, instance:Test_code.Test_01@39aeed2f]" name="code4" duration-ms="1" started-at="2019-08-18T05:12:01Z" finished-at="2019-08-18T05:12:01Z">
          <reporter-output>
          </reporter-output>
        </test-method> <!-- code4 -->
        <test-method status="PASS" signature="code5()[pri:5, instance:Test_code.Test_01@39aeed2f]" name="code5" duration-ms="1" started-at="2019-08-18T05:12:01Z" finished-at="2019-08-18T05:12:01Z">
          <reporter-output>
          </reporter-output>
        </test-method> <!-- code5 -->
      </class> <!-- Test_code.Test_01 -->
    </test> <!-- Test2 -->
    <test name="Test3" duration-ms="17" started-at="2019-08-18T05:12:01Z" finished-at="2019-08-18T05:12:01Z">
      <class name="Test_code.Test_01">
        <test-method status="FAIL" signature="code1()[pri:1, instance:Test_code.Test_01@55f3ddb1]" name="code1" duration-ms="1" started-at="2019-08-18T05:12:01Z" finished-at="2019-08-18T05:12:01Z">
          <exception class="java.lang.AssertionError">
            <message>
              <![CDATA[Test cases failed as we have false value: FAIL!!!!!!!!!!! expected [true] but found [false]]]>
            </message>
            <full-stacktrace>
              <![CDATA[java.lang.AssertionError: Test cases failed as we have false value: FAIL!!!!!!!!!!! expected [true] but found [false]
at org.testng.Assert.fail(Assert.java:96)
at org.testng.Assert.failNotEquals(Assert.java:776)
at org.testng.Assert.assertTrue(Assert.java:44)
at Test_code.Test_01.code1(Test_01.java:17)
at sun.reflect.NativeMethodAccessorImpl.invoke0(Native Method)
at sun.reflect.NativeMethodAccessorImpl.invoke(Unknown Source)
at sun.reflect.DelegatingMethodAccessorImpl.invoke(Unknown Source)
at java.lang.reflect.Method.invoke(Unknown Source)
at org.testng.internal.MethodInvocationHelper.invokeMethod(MethodInvocationHelper.java:124)
at org.testng.internal.Invoker.invokeMethod(Invoker.java:580)
at org.testng.internal.Invoker.invokeTestMethod(Invoker.java:716)
at org.testng.internal.Invoker.invokeTestMethods(Invoker.java:988)
at org.testng.internal.TestMethodWorker.invokeTestMethods(TestMethodWorker.java:125)
at org.testng.internal.TestMethodWorker.run(TestMethodWorker.java:109)
at org.testng.TestRunner.privateRun(TestRunner.java:648)
at org.testng.TestRunner.run(TestRunner.java:505)
at org.testng.SuiteRunner.runTest(SuiteRunner.java:455)
at org.testng.SuiteRunner.runSequentially(SuiteRunner.java:450)
at org.testng.SuiteRunner.privateRun(SuiteRunner.java:415)
at org.testng.SuiteRunner.run(SuiteRunner.java:364)
at org.testng.SuiteRunnerWorker.runSuite(SuiteRunnerWorker.java:52)
at org.testng.SuiteRunnerWorker.run(SuiteRunnerWorker.java:84)
at org.testng.TestNG.runSuitesSequentially(TestNG.java:1208)
at org.testng.TestNG.runSuitesLocally(TestNG.java:1137)
at org.testng.TestNG.runSuites(TestNG.java:1049)
at org.testng.TestNG.run(TestNG.java:1017)
at org.testng.remote.AbstractRemoteTestNG.run(AbstractRemoteTestNG.java:114)
at org.testng.remote.RemoteTestNG.initAndRun(RemoteTestNG.java:251)
at org.testng.remote.RemoteTestNG.main(RemoteTestNG.java:77)
]]>
            </full-stacktrace>
          </exception> <!-- java.lang.AssertionError -->
          <reporter-output>
          </reporter-output>
        </test-method> <!-- code1 -->
        <test-method status="PASS" signature="code2()[pri:2, instance:Test_code.Test_01@55f3ddb1]" name="code2" duration-ms="1" started-at="2019-08-18T05:12:01Z" finished-at="2019-08-18T05:12:01Z">
          <reporter-output>
          </reporter-output>
        </test-method> <!-- code2 -->
        <test-method status="PASS" signature="code3()[pri:3, instance:Test_code.Test_01@55f3ddb1]" name="code3" duration-ms="1" started-at="2019-08-18T05:12:01Z" finished-at="2019-08-18T05:12:01Z">
          <reporter-output>
          </reporter-output>
        </test-method> <!-- code3 -->
        <test-method status="PASS" signature="code4()[pri:4, instance:Test_code.Test_01@55f3ddb1]" name="code4" duration-ms="1" started-at="2019-08-18T05:12:01Z" finished-at="2019-08-18T05:12:01Z">
          <reporter-output>
          </reporter-output>
        </test-method> <!-- code4 -->
        <test-method status="PASS" signature="code5()[pri:5, instance:Test_code.Test_01@55f3ddb1]" name="code5" duration-ms="2" started-at="2019-08-18T05:12:01Z" finished-at="2019-08-18T05:12:01Z">
          <reporter-output>
          </reporter-output>
        </test-method> <!-- code5 -->
      </class> <!-- Test_code.Test_01 -->
    </test> <!-- Test3 -->
    <test name="Test4" duration-ms="13" started-at="2019-08-18T05:12:01Z" finished-at="2019-08-18T05:12:01Z">
      <class name="Test_code.Test_01">
        <test-method status="FAIL" signature="code1()[pri:1, instance:Test_code.Test_01@1d057a39]" name="code1" duration-ms="1" started-at="2019-08-18T05:12:01Z" finished-at="2019-08-18T05:12:01Z">
          <exception class="java.lang.AssertionError">
            <message>
              <![CDATA[Test cases failed as we have false value: FAIL!!!!!!!!!!! expected [true] but found [false]]]>
            </message>
            <full-stacktrace>
              <![CDATA[java.lang.AssertionError: Test cases failed as we have false value: FAIL!!!!!!!!!!! expected [true] but found [false]
at org.testng.Assert.fail(Assert.java:96)
at org.testng.Assert.failNotEquals(Assert.java:776)
at org.testng.Assert.assertTrue(Assert.java:44)
at Test_code.Test_01.code1(Test_01.java:17)
at sun.reflect.NativeMethodAccessorImpl.invoke0(Native Method)
at sun.reflect.NativeMethodAccessorImpl.invoke(Unknown Source)
at sun.reflect.DelegatingMethodAccessorImpl.invoke(Unknown Source)
at java.lang.reflect.Method.invoke(Unknown Source)
at org.testng.internal.MethodInvocationHelper.invokeMethod(MethodInvocationHelper.java:124)
at org.testng.internal.Invoker.invokeMethod(Invoker.java:580)
at org.testng.internal.Invoker.invokeTestMethod(Invoker.java:716)
at org.testng.internal.Invoker.invokeTestMethods(Invoker.java:988)
at org.testng.internal.TestMethodWorker.invokeTestMethods(TestMethodWorker.java:125)
at org.testng.internal.TestMethodWorker.run(TestMethodWorker.java:109)
at org.testng.TestRunner.privateRun(TestRunner.java:648)
at org.testng.TestRunner.run(TestRunner.java:505)
at org.testng.SuiteRunner.runTest(SuiteRunner.java:455)
at org.testng.SuiteRunner.runSequentially(SuiteRunner.java:450)
at org.testng.SuiteRunner.privateRun(SuiteRunner.java:415)
at org.testng.SuiteRunner.run(SuiteRunner.java:364)
at org.testng.SuiteRunnerWorker.runSuite(SuiteRunnerWorker.java:52)
at org.testng.SuiteRunnerWorker.run(SuiteRunnerWorker.java:84)
at org.testng.TestNG.runSuitesSequentially(TestNG.java:1208)
at org.testng.TestNG.runSuitesLocally(TestNG.java:1137)
at org.testng.TestNG.runSuites(TestNG.java:1049)
at org.testng.TestNG.run(TestNG.java:1017)
at org.testng.remote.AbstractRemoteTestNG.run(AbstractRemoteTestNG.java:114)
at org.testng.remote.RemoteTestNG.initAndRun(RemoteTestNG.java:251)
at org.testng.remote.RemoteTestNG.main(RemoteTestNG.java:77)
]]>
            </full-stacktrace>
          </exception> <!-- java.lang.AssertionError -->
          <reporter-output>
          </reporter-output>
        </test-method> <!-- code1 -->
        <test-method status="PASS" signature="code2()[pri:2, instance:Test_code.Test_01@1d057a39]" name="code2" duration-ms="2" started-at="2019-08-18T05:12:01Z" finished-at="2019-08-18T05:12:01Z">
          <reporter-output>
          </reporter-output>
        </test-method> <!-- code2 -->
        <test-method status="PASS" signature="code3()[pri:3, instance:Test_code.Test_01@1d057a39]" name="code3" duration-ms="1" started-at="2019-08-18T05:12:01Z" finished-at="2019-08-18T05:12:01Z">
          <reporter-output>
          </reporter-output>
        </test-method> <!-- code3 -->
        <test-method status="PASS" signature="code4()[pri:4, instance:Test_code.Test_01@1d057a39]" name="code4" duration-ms="1" started-at="2019-08-18T05:12:01Z" finished-at="2019-08-18T05:12:01Z">
          <reporter-output>
          </reporter-output>
        </test-method> <!-- code4 -->
        <test-method status="PASS" signature="code5()[pri:5, instance:Test_code.Test_01@1d057a39]" name="code5" duration-ms="1" started-at="2019-08-18T05:12:01Z" finished-at="2019-08-18T05:12:01Z">
          <reporter-output>
          </reporter-output>
        </test-method> <!-- code5 -->
      </class> <!-- Test_code.Test_01 -->
    </test> <!-- Test4 -->
    <test name="Test5" duration-ms="17" started-at="2019-08-18T05:12:01Z" finished-at="2019-08-18T05:12:01Z">
      <class name="Test_code.Test_01">
        <test-method status="FAIL" signature="code1()[pri:1, instance:Test_code.Test_01@59fa1d9b]" name="code1" duration-ms="1" started-at="2019-08-18T05:12:01Z" finished-at="2019-08-18T05:12:01Z">
          <exception class="java.lang.AssertionError">
            <message>
              <![CDATA[Test cases failed as we have false value: FAIL!!!!!!!!!!! expected [true] but found [false]]]>
            </message>
            <full-stacktrace>
              <![CDATA[java.lang.AssertionError: Test cases failed as we have false value: FAIL!!!!!!!!!!! expected [true] but found [false]
at org.testng.Assert.fail(Assert.java:96)
at org.testng.Assert.failNotEquals(Assert.java:776)
at org.testng.Assert.assertTrue(Assert.java:44)
at Test_code.Test_01.code1(Test_01.java:17)
at sun.reflect.NativeMethodAccessorImpl.invoke0(Native Method)
at sun.reflect.NativeMethodAccessorImpl.invoke(Unknown Source)
at sun.reflect.DelegatingMethodAccessorImpl.invoke(Unknown Source)
at java.lang.reflect.Method.invoke(Unknown Source)
at org.testng.internal.MethodInvocationHelper.invokeMethod(MethodInvocationHelper.java:124)
at org.testng.internal.Invoker.invokeMethod(Invoker.java:580)
at org.testng.internal.Invoker.invokeTestMethod(Invoker.java:716)
at org.testng.internal.Invoker.invokeTestMethods(Invoker.java:988)
at org.testng.internal.TestMethodWorker.invokeTestMethods(TestMethodWorker.java:125)
at org.testng.internal.TestMethodWorker.run(TestMethodWorker.java:109)
at org.testng.TestRunner.privateRun(TestRunner.java:648)
at org.testng.TestRunner.run(TestRunner.java:505)
at org.testng.SuiteRunner.runTest(SuiteRunner.java:455)
at org.testng.SuiteRunner.runSequentially(SuiteRunner.java:450)
at org.testng.SuiteRunner.privateRun(SuiteRunner.java:415)
at org.testng.SuiteRunner.run(SuiteRunner.java:364)
at org.testng.SuiteRunnerWorker.runSuite(SuiteRunnerWorker.java:52)
at org.testng.SuiteRunnerWorker.run(SuiteRunnerWorker.java:84)
at org.testng.TestNG.runSuitesSequentially(TestNG.java:1208)
at org.testng.TestNG.runSuitesLocally(TestNG.java:1137)
at org.testng.TestNG.runSuites(TestNG.java:1049)
at org.testng.TestNG.run(TestNG.java:1017)
at org.testng.remote.AbstractRemoteTestNG.run(AbstractRemoteTestNG.java:114)
at org.testng.remote.RemoteTestNG.initAndRun(RemoteTestNG.java:251)
at org.testng.remote.RemoteTestNG.main(RemoteTestNG.java:77)
]]>
            </full-stacktrace>
          </exception> <!-- java.lang.AssertionError -->
          <reporter-output>
          </reporter-output>
        </test-method> <!-- code1 -->
        <test-method status="PASS" signature="code2()[pri:2, instance:Test_code.Test_01@59fa1d9b]" name="code2" duration-ms="2" started-at="2019-08-18T05:12:01Z" finished-at="2019-08-18T05:12:01Z">
          <reporter-output>
          </reporter-output>
        </test-method> <!-- code2 -->
        <test-method status="PASS" signature="code3()[pri:3, instance:Test_code.Test_01@59fa1d9b]" name="code3" duration-ms="0" started-at="2019-08-18T05:12:01Z" finished-at="2019-08-18T05:12:01Z">
          <reporter-output>
          </reporter-output>
        </test-method> <!-- code3 -->
        <test-method status="PASS" signature="code4()[pri:4, instance:Test_code.Test_01@59fa1d9b]" name="code4" duration-ms="0" started-at="2019-08-18T05:12:01Z" finished-at="2019-08-18T05:12:01Z">
          <reporter-output>
          </reporter-output>
        </test-method> <!-- code4 -->
        <test-method status="PASS" signature="code5()[pri:5, instance:Test_code.Test_01@59fa1d9b]" name="code5" duration-ms="1" started-at="2019-08-18T05:12:01Z" finished-at="2019-08-18T05:12:01Z">
          <reporter-output>
          </reporter-output>
        </test-method> <!-- code5 -->
      </class> <!-- Test_code.Test_01 -->
    </test> <!-- Test5 -->
  </suite> <!-- Suite -->
</testng-results>
